Workbook

Sheet Indices de Tabelas
A1: Tabela Casa 7 | B1: Percentual | C1: Multiplicador
A2: Tabela RS, SC, PR | B2: 0.07 | C2: =(1+B2) -> 1.07

Sheet Tabela Base Casa 7 Brasil
A3: TABELA COMERCIAL CASA 7 - VÁLIDA A PARTIR DE 01/10/2020
A5: Mesas de Jantar
A7: 7MJT003 MESA DE JANTAR SPIN
B8: Acabamento Tampo | C8: Larg. | E8: Prof. | G8: Alt. | I8: Tabela
B9: Madeirado / Envidraçado Reto | C9: 1.2 | D9: X | E9: 0.9 | F9: X | G9: 0.78 | I9: 1061.8966
B10: Madeirado / Envidraçado Reto | C10: 1.4 | D10: X | E10: 0.9 | F10: X | G10: 0.78 | I10: 1112.9891
B11: Madeirado / Envidraçado Reto | C11: 1.35 | D11: X | E11: 1.35 | F11: X | G11: 0.78 | I11: 1401.593
B12: Madeirado / Envidraçado Moeda OU Copo | C12: 1.2 | D12: X | E12: 0.9 | F12: X | G12: 0.78 | I12: 1093.6568
B13: Madeirado / Envidraçado Moeda OU Copo | C13: 1.4 | D13: X | E13: 0.9 | F13: X | G13: 0.78 | I13: 1158.5581
B14: Madeirado / Envidraçado Moeda OU Copo | C14: 1.35 | D14: X | E14: 1.35 | F14: X | G14: 0.78 | I14: 1528.6339
B15: Madeirado / Envidraçado Barril | C15: 1.2 | D15: X | E15: 0.9 | F15: X | G15: 0.78 | I15: 1093.6568
B16: Madeirado / Envidraçado Redonda | C16: 1 | D16: X | E16: 1 | F16: X | G16: 0.78 | I16: 1086.7524
B17: Madeirado / Envidraçado Redonda | C17: 1.3 | D17: X | E17: 1.3 | F17: X | G17: 0.78 | I17: 1347.7387
A19: 7MJT005 MESA DE JANTAR TURN
B20: Acabamento Tampo | C20: Larg. | E20: Prof. | G20: Alt. | I20: Tabela
B21: Madeirado / Envidraçado Reto | C21: 1.2 | D21: X | E21: 0.9 | F21: X | G21: 0.78 | I21: 1143.3685
B22: Madeirado / Envidraçado Reto | C22: 1.4 | D22: X | E22: 0.9 | F22: X | G22: 0.78 | I22: 1193.0801
B23: Madeirado / Envidraçado Reto | C23: 1.6 | D23: X | E23: 1 | F23: X | G23: 0.78 | I23: 1343.596
B24: Madeirado / Envidraçado Reto | C24: 1.8 | D24: X | E24: 1 | F24: X | G24: 0.78 | I24: 1400.2121
B25: Madeirado / Envidraçado Reto | C25: 2 | D25: X | E25: 1 | F25: X | G25: 0.78 | I25: 1459.5899
B26: Madeirado / Envidraçado Reto | C26: 2.2 | D26: X | E26: 1.1 | F26: X | G26: 0.78 | I26: 1651.5322
B27: Madeirado / Envidraçado Reto | C27: 1.35 | D27: X | E27: 1.35 | F27: X | G27: 0.78 | I27: 1398.8312
B28: Madeirado / Envidraçado Moeda OU Copo | C28: 1.2 | D28: X | E28: 0.9 | F28: X | G28: 0.78 | I28: 1173.7478
B29: Madeirado / Envidraçado Moeda OU Copo | C29: 1.4 | D29: X | E29: 0.9 | F29: X | G29: 0.78 | I29: 1228.983
B30: Madeirado / Envidraçado Moeda OU Copo | C30: 1.6 | D30: X | E30: 1 | F30: X | G30: 0.78 | I30: 1389.1651
B31: Madeirado / Envidraçado Moeda OU Copo | C31: 1.8 | D31: X | E31: 1 | F31: X | G31: 0.78 | I31: 1474.7796
B32: Madeirado / Envidraçado Moeda OU Copo | C32: 2 | D32: X | E32: 1 | F32: X | G32: 0.78 | I32: 1539.681
B33: Madeirado / Envidraçado Moeda OU Copo | C33: 2.2 | D33: X | E33: 1.1 | F33: X | G33: 0.78 | H33: 0.78 | I33: 1818.6187
B34: Madeirado / Envidraçado Moeda OU Copo | C34: 1.35 | D34: X | E34: 1.35 | F34: X | G34: 0.78 | I34: 1524.4913
B35: Madeirado / Envidraçado Barril | C35: 1.2 | D35: X | E35: 0.9 | F35: X | G35: 0.78 | I35: 1173.7478
B36: Madeirado / Envidraçado Barril | C36: 1.8 | D36: X | E36: 1 | F36: X | G36: 0.78 | I36: 1474.7796
A38: 7MJT015 MESA DE JANTAR MONARCA
B39: Acabamento Tampo | C39: Larg. | E39: Prof. | G39: Alt. | I39: Tabela
B40: Madeirado / Envidraçado Redondo | C40: 1.2 | D40: X | E40: 1.2 | F40: X | G40: 0.78 | I40: 1639.1043
B41: Madeirado / Envidraçado Redondo | C41: 1.3 | D41: X | E41: 1.3 | F41: X | G41: 0.78 | I41: 1705.3865
B42: Madeirado / Envidraçado Redondo | C42: 1.5 | D42: X | E42: 1.5 | F42: X | G42: 0.78 | I42: 1969.1346
A44: 7MJT016 MESA DE JANTAR DIAMANTE
B45: Acabamento Tampo | C45: Larg. | E45: Prof. | G45: Alt. | I45: Tabela
B46: Madeirado / Envidraçado Reto | C46: 1.8 | D46: X | E46: 1 | F46: X | G46: 0.78 | I46: 1554.8706
B47: Madeirado / Envidraçado Reto | C47: 2 | D47: X | E47: 1 | F47: X | G47: 0.78 | I47: 1695.7204
...

Sheet Tabela Casa 7 RS
L1: Percentual desconto comercial | M1: 0.18
A3: TABELA COMERCIAL CASA 7 - VÁLIDA A PARTIR DE 01/01/2021
A5: Acrescentar 5% referente a IPI
A7: Mesas de Jantar
A9: 7MJT003 MESA DE JANTAR SPIN
B10: Acabamento Tampo | C10: Larg. | E10: Prof. | G10: Alt. | I10: Tabela | J10: Antecipado | K10: Á Vista : 21+6% | L10: 30 Dias : 21+3% | M10: 60 Dias : 21%
B11: Madeirado / Envidraçado Reto | C11: 1.2 | D11: X | E11: 0.9 | F11: X | G11: 0.78 | I11: ='Tabela Base Casa 7 Brasil'!I9*'Indices de Tabelas'!$C$2 -> 1136.2293 | J11: =ROUNDDOWN((I11*(1-$C$274)*(1-$E$274)*(1-$G$274)),0) -> 840 | K11: =I11*(1-$C$275)*(1-$E$275) -> 875.80556 | L11: =I11*(1-$C$276)*(1-$E$275) -> 875.80556 | M11: =I11*(1-$C$277) -> 931.70804
B12: Madeirado / Envidraçado Reto | C12: 1.4 | D12: X | E12: 0.9 | F12: X | G12: 0.78 | I12: ='Tabela Base Casa 7 Brasil'!I10*'Indices de Tabelas'!$C$2 -> 1190.8983 | J12: =ROUNDDOWN((I12*(1-$C$274)*(1-$E$274)*(1-$G$274)),0) -> 881 | K12: =I12*(1-$C$275)*(1-$E$275) -> 917.94444 | L12: =I12*(1-$C$276)*(1-$E$275) -> 917.94444 | M12: =I12*(1-$C$277) -> 976.53664
B13: Madeirado / Envidraçado Reto | C13: 1.35 | D13: X | E13: 1.35 | F13: X | G13: 0.78 | I13: ='Tabela Base Casa 7 Brasil'!I11*'Indices de Tabelas'!$C$2 -> 1499.7045 | J13: =ROUNDDOWN((I13*(1-$C$274)*(1-$E$274)*(1-$G$274)),0) -> 1109 | K13: =I13*(1-$C$275)*(1-$E$275) -> 1155.9722 | L13: =I13*(1-$C$276)*(1-$E$275) -> 1155.9722 | M13: =I13*(1-$C$277) -> 1229.7577
B14: Madeirado / Envidraçado Moeda OU Copo | C14: 1.2 | D14: X | E14: 0.9 | F14: X | G14: 0.78 | I14: ='Tabela Base Casa 7 Brasil'!I12*'Indices de Tabelas'!$C$2 -> 1170.2128 | J14: =ROUNDDOWN((I14*(1-$C$274)*(1-$E$274)*(1-$G$274)),0) -> 865 | K14: =I14*(1-$C$275)*(1-$E$275) -> 902 | L14: =I14*(1-$C$276)*(1-$E$275) -> 902 | M14: =I14*(1-$C$277) -> 959.57447
B15: Madeirado / Envidraçado Moeda OU Copo | C15: 1.4 | D15: X | E15: 0.9 | F15: X | G15: 0.78 | I15: ='Tabela Base Casa 7 Brasil'!I13*'Indices de Tabelas'!$C$2 -> 1239.6572 | J15: =ROUNDDOWN((I15*(1-$C$274)*(1-$E$274)*(1-$G$274)),0) -> 917 | K15: =I15*(1-$C$275)*(1-$E$275) -> 955.52778 | L15: =I15*(1-$C$276)*(1-$E$275) -> 955.52778 | M15: =I15*(1-$C$277) -> 1016.5189
B16: Madeirado / Envidraçado Moeda OU Copo | C16: 1.35 | D16: X | E16: 1.35 | F16: X | G16: 0.78 | I16: ='Tabela Base Casa 7 Brasil'!I14*'Indices de Tabelas'!$C$2 -> 1635.6383 | J16: =ROUNDDOWN((I16*(1-$C$274)*(1-$E$274)*(1-$G$274)),0) -> 1210 | K16: =I16*(1-$C$275)*(1-$E$275) -> 1260.75 | L16: =I16*(1-$C$276)*(1-$E$275) -> 1260.75 | M16: =I16*(1-$C$277) -> 1341.2234
B17: Madeirado / Envidraçado Barril | C17: 1.2 | D17: X | E17: 0.9 | F17: X | G17: 0.78 | I17: ='Tabela Base Casa 7 Brasil'!I15*'Indices de Tabelas'!$C$2 -> 1170.2128 | J17: =ROUNDDOWN((I17*(1-$C$274)*(1-$E$274)*(1-$G$274)),0) -> 865 | K17: =I17*(1-$C$275)*(1-$E$275) -> 902 | L17: =I17*(1-$C$276)*(1-$E$275) -> 902 | M17: =I17*(1-$C$277) -> 959.57447
B18: Madeirado / Envidraçado Redonda | C18: 1 | D18: X | E18: 1 | F18: X | G18: 0.78 | I18: ='Tabela Base Casa 7 Brasil'!I16*'Indices de Tabelas'!$C$2 -> 1162.8251 | J18: =ROUNDDOWN((I18*(1-$C$274)*(1-$E$274)*(1-$G$274)),0) -> 860 | K18: =I18*(1-$C$275)*(1-$E$275) -> 896.30556 | L18: =I18*(1-$C$276)*(1-$E$275) -> 896.30556 | M18: =I18*(1-$C$277) -> 953.51655
B19: Madeirado / Envidraçado Redonda | C19: 1.3 | D19: X | E19: 1.3 | F19: X | G19: 0.78 | I19: ='Tabela Base Casa 7 Brasil'!I17*'Indices de Tabelas'!$C$2 -> 1442.0804 | J19: =ROUNDDOWN((I19*(1-$C$274)*(1-$E$274)*(1-$G$274)),0) -> 1067 | K19: =I19*(1-$C$275)*(1-$E$275) -> 1111.5556 | L19: =I19*(1-$C$276)*(1-$E$275) -> 1111.5556 | M19: =I19*(1-$C$277) -> 1182.5059
A21: 7MJT005 MESA DE JANTAR TURN
B22: Acabamento Tampo | C22: Larg. | E22: Prof. | G22: Alt. | I22: Tabela | J22: Antecipado | K22: Á Vista : 21+6% | L22: 30 Dias : 21+3% | M22: 60 Dias : 21%
B23: Madeirado / Envidraçado Reto | C23: 1.2 | D23: X | E23: 0.9 | F23: X | G23: 0.78 | I23: ='Tabela Base Casa 7 Brasil'!I21*'Indices de Tabelas'!$C$2 -> 1223.4043 | J23: =ROUNDDOWN((I23*(1-$C$274)*(1-$E$274)*(1-$G$274)),0) -> 905 | K23: =I23*(1-$C$275)*(1-$E$275) -> 943 | L23: =I23*(1-$C$276)*(1-$E$275) -> 943 | M23: =I23*(1-$C$277) -> 1003.1915
B24: Madeirado / Envidraçado Reto | C24: 1.4 | D24: X | E24: 0.9 | F24: X | G24: 0.78 | I24: ='Tabela Base Casa 7 Brasil'!I22*'Indices de Tabelas'!$C$2 -> 1276.5957 | J24: =ROUNDDOWN((I24*(1-$C$274)*(1-$E$274)*(1-$G$274)),0) -> 944 | K24: =I24*(1-$C$275)*(1-$E$275) -> 984 | L24: =I24*(1-$C$276)*(1-$E$275) -> 984 | M24: =I24*(1-$C$277) -> 1046.8085
B25: Madeirado / Envidraçado Reto | C25: 1.6 | D25: X | E25: 1 | F25: X | G25: 0.78 | I25: ='Tabela Base Casa 7 Brasil'!I23*'Indices de Tabelas'!$C$2 -> 1437.6478 | J25: =ROUNDDOWN((I25*(1-$C$274)*(1-$E$274)*(1-$G$274)),0) -> 1063 | K25: =I25*(1-$C$275)*(1-$E$275) -> 1108.1389 | L25: =I25*(1-$C$276)*(1-$E$275) -> 1108.1389 | M25: =I25*(1-$C$277) -> 1178.8712
B26: Madeirado / Envidraçado Reto | C26: 1.8 | D26: X | E26: 1 | F26: X | G26: 0.78 | I26: ='Tabela Base Casa 7 Brasil'!I24*'Indices de Tabelas'!$C$2 -> 1498.227 | J26: =ROUNDDOWN((I26*(1-$C$274)*(1-$E$274)*(1-$G$274)),0) -> 1108 | K26: =I26*(1-$C$275)*(1-$E$275) -> 1154.8333 | L26: =I26*(1-$C$276)*(1-$E$275) -> 1154.8333 | M26: =I26*(1-$C$277) -> 1228.5461
B27: Madeirado / Envidraçado Reto | C27: 2 | D27: X | E27: 1 | F27: X | G27: 0.78 | I27: ='Tabela Base Casa 7 Brasil'!I25*'Indices de Tabelas'!$C$2 -> 1561.7612 | J27: =ROUNDDOWN((I27*(1-$C$274)*(1-$E$274)*(1-$G$274)),0) -> 1155 | K27: =I27*(1-$C$275)*(1-$E$275) -> 1203.8056 | L27: =I27*(1-$C$276)*(1-$E$275) -> 1203.8056 | M27: =I27*(1-$C$277) -> 1280.6442
B28: Madeirado / Envidraçado Reto | C28: 2.2 | D28: X | E28: 1.1 | F28: X | G28: 0.78 | I28: ='Tabela Base Casa 7 Brasil'!I26*'Indices de Tabelas'!$C$2 -> 1767.1395 | J28: =ROUNDDOWN((I28*(1-$C$274)*(1-$E$274)*(1-$G$274)),0) -> 1307 | K28: =I28*(1-$C$275)*(1-$E$275) -> 1362.1111 | L28: =I28*(1-$C$276)*(1-$E$275) -> 1362.1111 | M28: =I28*(1-$C$277) -> 1449.0544
B29: Madeirado / Envidraçado Reto | C29: 1.35 | D29: X | E29: 1.35 | F29: X | G29: 0.78 | I29: ='Tabela Base Casa 7 Brasil'!I27*'Indices de Tabelas'!$C$2 -> 1496.7494 | J29: =ROUNDDOWN((I29*(1-$C$274)*(1-$E$274)*(1-$G$274)),0) -> 1107 | K29: =I29*(1-$C$275)*(1-$E$275) -> 1153.6944 | L29: =I29*(1-$C$276)*(1-$E$275) -> 1153.6944 | M29: =I29*(1-$C$277) -> 1227.3345
B30: Madeirado / Envidraçado Moeda OU Copo | C30: 1.2 | D30: X | E30: 0.9 | F30: X | G30: 0.78 | I30: ='Tabela Base Casa 7 Brasil'!I28*'Indices de Tabelas'!$C$2 -> 1255.9102 | J30: =ROUNDDOWN((I30*(1-$C$274)*(1-$E$274)*(1-$G$274)),0) -> 929 | K30: =I30*(1-$C$275)*(1-$E$275) -> 968.05556 | L30: =I30*(1-$C$276)*(1-$E$275) -> 968.05556 | M30: =I30*(1-$C$277) -> 1029.8463
B31: Madeirado / Envidraçado Moeda OU Copo | C31: 1.4 | D31: X | E31: 0.9 | F31: X | G31: 0.78 | I31: ='Tabela Base Casa 7 Brasil'!I29*'Indices de Tabelas'!$C$2 -> 1315.0118 | J31: =ROUNDDOWN((I31*(1-$C$274)*(1-$E$274)*(1-$G$274)),0) -> 973 | K31: =I31*(1-$C$275)*(1-$E$275) -> 1013.6111 | L31: =I31*(1-$C$276)*(1-$E$275) -> 1013.6111 | M31: =I31*(1-$C$277) -> 1078.3097
B32: Madeirado / Envidraçado Moeda OU Copo | C32: 1.6 | D32: X | E32: 1 | F32: X | G32: 0.78 | I32: ='Tabela Base Casa 7 Brasil'!I30*'Indices de Tabelas'!$C$2 -> 1486.4066 | J32: =ROUNDDOWN((I32*(1-$C$274)*(1-$E$274)*(1-$G$274)),0) -> 1099 | K32: =I32*(1-$C$275)*(1-$E$275) -> 1145.7222 | L32: =I32*(1-$C$276)*(1-$E$275) -> 1145.7222 | M32: =I32*(1-$C$277) -> 1218.8534
B33: Madeirado / Envidraçado Moeda OU Copo | C33: 1.8 | D33: X | E33: 1 | F33: X | G33: 0.78 | I33: ='Tabela Base Casa 7 Brasil'!I31*'Indices de Tabelas'!$C$2 -> 1578.0142 | J33: =ROUNDDOWN((I33*(1-$C$274)*(1-$E$274)*(1-$G$274)),0) -> 1167 | K33: =I33*(1-$C$275)*(1-$E$275) -> 1216.3333 | L33: =I33*(1-$C$276)*(1-$E$275) -> 1216.3333 | M33: =I33*(1-$C$277) -> 1293.9716
B34: Madeirado / Envidraçado Moeda OU Copo | C34: 2 | D34: X | E34: 1 | F34: X | G34: 0.78 | I34: ='Tabela Base Casa 7 Brasil'!I32*'Indices de Tabelas'!$C$2 -> 1647.4586 | J34: =ROUNDDOWN((I34*(1-$C$274)*(1-$E$274)*(1-$G$274)),0) -> 1219 | K34: =I34*(1-$C$275)*(1-$E$275) -> 1269.8611 | L34: =I34*(1-$C$276)*(1-$E$275) -> 1269.8611 | M34: =I34*(1-$C$277) -> 1350.9161
B35: Madeirado / Envidraçado Moeda OU Copo | C35: 2.2 | D35: X | E35: 1.1 | F35: X | G35: 0.78 | H35: 0.78 | I35: ='Tabela Base Casa 7 Brasil'!I33*'Indices de Tabelas'!$C$2 -> 1945.922 | J35: =ROUNDDOWN((I35*(1-$C$274)*(1-$E$274)*(1-$G$274)),0) -> 1439 | K35: =I35*(1-$C$275)*(1-$E$275) -> 1499.9167 | L35: =I35*(1-$C$276)*(1-$E$275) -> 1499.9167 | M35: =I35*(1-$C$277) -> 1595.656
B36: Madeirado / Envidraçado Moeda OU Copo | C36: 1.35 | D36: X | E36: 1.35 | F36: X | G36: 0.78 | I36: ='Tabela Base Casa 7 Brasil'!I34*'Indices de Tabelas'!$C$2 -> 1631.2057 | J36: =ROUNDDOWN((I36*(1-$C$274)*(1-$E$274)*(1-$G$274)),0) -> 1207 | K36: =I36*(1-$C$275)*(1-$E$275) -> 1257.3333 | L36: =I36*(1-$C$276)*(1-$E$275) -> 1257.3333 | M36: =I36*(1-$C$277) -> 1337.5887
B37: Madeirado / Envidraçado Barril | C37: 1.2 | D37: X | E37: 0.9 | F37: X | G37: 0.78 | I37: ='Tabela Base Casa 7 Brasil'!I35*'Indices de Tabelas'!$C$2 -> 1255.9102 | J37: =ROUNDDOWN((I37*(1-$C$274)*(1-$E$274)*(1-$G$274)),0) -> 929 | K37: =I37*(1-$C$275)*(1-$E$275) -> 968.05556 | L37: =I37*(1-$C$276)*(1-$E$275) -> 968.05556 | M37: =I37*(1-$C$277) -> 1029.8463
B38: Madeirado / Envidraçado Barril | C38: 1.8 | D38: X | E38: 1 | F38: X | G38: 0.78 | I38: ='Tabela Base Casa 7 Brasil'!I36*'Indices de Tabelas'!$C$2 -> 1578.0142 | J38: =ROUNDDOWN((I38*(1-$C$274)*(1-$E$274)*(1-$G$274)),0) -> 1167 | K38: =I38*(1-$C$275)*(1-$E$275) -> 1216.3333 | L38: =I38*(1-$C$276)*(1-$E$275) -> 1216.3333 | M38: =I38*(1-$C$277) -> 1293.9716
A40: 7MJT015 MESA DE JANTAR MONARCA
B41: Acabamento Tampo | C41: Larg. | E41: Prof. | G41: Alt. | I41: Tabela | J41: Antecipado | K41: Á Vista : 21+6% | L41: 30 Dias : 21+3% | M41: 60 Dias : 21%
B42: Madeirado / Envidraçado Redondo | C42: 1.2 | D42: X | E42: 1.2 | F42: X | G42: 0.78 | I42: ='Tabela Base Casa 7 Brasil'!I40*'Indices de Tabelas'!$C$2 -> 1753.8416 | J42: =ROUNDDOWN((I42*(1-$C$274)*(1-$E$274)*(1-$G$274)),0) -> 1297 | K42: =I42*(1-$C$275)*(1-$E$275) -> 1351.8611 | L42: =I42*(1-$C$276)*(1-$E$275) -> 1351.8611 | M42: =I42*(1-$C$277) -> 1438.1501
B43: Madeirado / Envidraçado Redondo | C43: 1.3 | D43: X | E43: 1.3 | F43: X | G43: 0.78 | I43: ='Tabela Base Casa 7 Brasil'!I41*'Indices de Tabelas'!$C$2 -> 1824.7636 | J43: =ROUNDDOWN((I43*(1-$C$274)*(1-$E$274)*(1-$G$274)),0) -> 1350 | K43: =I43*(1-$C$275)*(1-$E$275) -> 1406.5278 | L43: =I43*(1-$C$276)*(1-$E$275) -> 1406.5278 | M43: =I43*(1-$C$277) -> 1496.3061
B44: Madeirado / Envidraçado Redondo | C44: 1.5 | D44: X | E44: 1.5 | F44: X | G44: 0.78 | I44: ='Tabela Base Casa 7 Brasil'!I42*'Indices de Tabelas'!$C$2 -> 2106.974 | J44: =ROUNDDOWN((I44*(1-$C$274)*(1-$E$274)*(1-$G$274)),0) -> 1559 | K44: =I44*(1-$C$275)*(1-$E$275) -> 1624.0556 | L44: =I44*(1-$C$276)*(1-$E$275) -> 1624.0556 | M44: =I44*(1-$C$277) -> 1727.7187
A46: 7MJT016 MESA DE JANTAR DIAMANTE
B47: Acabamento Tampo | C47: Larg. | E47: Prof. | G47: Alt. | I47: Tabela | J47: Antecipado | K47: Á Vista : 21+6% | L47: 30 Dias : 21+3% | M47: 60 Dias : 21%
...

Sheet Tabela Casa 7 Brasil
L1: Percentual desconto comercial | M1: 0.21
A3: TABELA COMERCIAL CASA 7 - VÁLIDA A PARTIR DE 01/01/2021
A5: Acrescentar 5% referente a IPI
A7: Mesas de Jantar
A9: 7MJT003 MESA DE JANTAR SPIN
B10: Acabamento Tampo | C10: Larg. | E10: Prof. | G10: Alt. | I10: Tabela | J10: Antecipado | K10: Á Vista : 21+6% | L10: 30 Dias : 21+3% | M10: 60 Dias : 21%
B11: Madeirado / Envidraçado Reto | C11: 1.2 | D11: X | E11: 0.9 | F11: X | G11: 0.78 | I11: ='Tabela Base Casa 7 Brasil'!I9*'Indices de Tabelas'!$C$2 -> 1136.2293 | J11: =ROUNDDOWN((I11*(1-$C$274)*(1-$E$274)*(1-$G$274)),0) -> 810 | K11: =I11*(1-$C$275)*(1-$E$275) -> 843.76389 | L11: =I11*(1-$C$276)*(1-$E$275) -> 843.76389 | M11: =I11*(1-$C$277) -> 897.62116
B12: Madeirado / Envidraçado Reto | C12: 1.4 | D12: X | E12: 0.9 | F12: X | G12: 0.78 | I12: ='Tabela Base Casa 7 Brasil'!I10*'Indices de Tabelas'!$C$2 -> 1190.8983 | J12: =ROUNDDOWN((I12*(1-$C$274)*(1-$E$274)*(1-$G$274)),0) -> 848 | K12: =I12*(1-$C$275)*(1-$E$275) -> 884.36111 | L12: =I12*(1-$C$276)*(1-$E$275) -> 884.36111 | M12: =I12*(1-$C$277) -> 940.80969
B13: Madeirado / Envidraçado Reto | C13: 1.35 | D13: X | E13: 1.35 | F13: X | G13: 0.78 | I13: ='Tabela Base Casa 7 Brasil'!I11*'Indices de Tabelas'!$C$2 -> 1499.7045 | J13: =ROUNDDOWN((I13*(1-$C$274)*(1-$E$274)*(1-$G$274)),0) -> 1069 | K13: =I13*(1-$C$275)*(1-$E$275) -> 1113.6806 | L13: =I13*(1-$C$276)*(1-$E$275) -> 1113.6806 | M13: =I13*(1-$C$277) -> 1184.7665
B14: Madeirado / Envidraçado Moeda OU Copo | C14: 1.2 | D14: X | E14: 0.9 | F14: X | G14: 0.78 | I14: ='Tabela Base Casa 7 Brasil'!I12*'Indices de Tabelas'!$C$2 -> 1170.2128 | J14: =ROUNDDOWN((I14*(1-$C$274)*(1-$E$274)*(1-$G$274)),0) -> 834 | K14: =I14*(1-$C$275)*(1-$E$275) -> 869 | L14: =I14*(1-$C$276)*(1-$E$275) -> 869 | M14: =I14*(1-$C$277) -> 924.46809
B15: Madeirado / Envidraçado Moeda OU Copo | C15: 1.4 | D15: X | E15: 0.9 | F15: X | G15: 0.78 | I15: ='Tabela Base Casa 7 Brasil'!I13*'Indices de Tabelas'!$C$2 -> 1239.6572 | J15: =ROUNDDOWN((I15*(1-$C$274)*(1-$E$274)*(1-$G$274)),0) -> 883 | K15: =I15*(1-$C$275)*(1-$E$275) -> 920.56944 | L15: =I15*(1-$C$276)*(1-$E$275) -> 920.56944 | M15: =I15*(1-$C$277) -> 979.3292
B16: Madeirado / Envidraçado Moeda OU Copo | C16: 1.35 | D16: X | E16: 1.35 | F16: X | G16: 0.78 | I16: ='Tabela Base Casa 7 Brasil'!I14*'Indices de Tabelas'!$C$2 -> 1635.6383 | J16: =ROUNDDOWN((I16*(1-$C$274)*(1-$E$274)*(1-$G$274)),0) -> 1166 | K16: =I16*(1-$C$275)*(1-$E$275) -> 1214.625 | L16: =I16*(1-$C$276)*(1-$E$275) -> 1214.625 | M16: =I16*(1-$C$277) -> 1292.1543
B17: Madeirado / Envidraçado Barril | C17: 1.2 | D17: X | E17: 0.9 | F17: X | G17: 0.78 | I17: ='Tabela Base Casa 7 Brasil'!I15*'Indices de Tabelas'!$C$2 -> 1170.2128 | J17: =ROUNDDOWN((I17*(1-$C$274)*(1-$E$274)*(1-$G$274)),0) -> 834 | K17: =I17*(1-$C$275)*(1-$E$275) -> 869 | L17: =I17*(1-$C$276)*(1-$E$275) -> 869 | M17: =I17*(1-$C$277) -> 924.46809
B18: Madeirado / Envidraçado Redonda | C18: 1 | D18: X | E18: 1 | F18: X | G18: 0.78 | I18: ='Tabela Base Casa 7 Brasil'!I16*'Indices de Tabelas'!$C$2 -> 1162.8251 | J18: =ROUNDDOWN((I18*(1-$C$274)*(1-$E$274)*(1-$G$274)),0) -> 828 | K18: =I18*(1-$C$275)*(1-$E$275) -> 863.51389 | L18: =I18*(1-$C$276)*(1-$E$275) -> 863.51389 | M18: =I18*(1-$C$277) -> 918.6318
B19: Madeirado / Envidraçado Redonda | C19: 1.3 | D19: X | E19: 1.3 | F19: X | G19: 0.78 | I19: ='Tabela Base Casa 7 Brasil'!I17*'Indices de Tabelas'!$C$2 -> 1442.0804 | J19: =ROUNDDOWN((I19*(1-$C$274)*(1-$E$274)*(1-$G$274)),0) -> 1028 | K19: =I19*(1-$C$275)*(1-$E$275) -> 1070.8889 | L19: =I19*(1-$C$276)*(1-$E$275) -> 1070.8889 | M19: =I19*(1-$C$277) -> 1139.2435
A21: 7MJT005 MESA DE JANTAR TURN
B22: Acabamento Tampo | C22: Larg. | E22: Prof. | G22: Alt. | I22: Tabela | J22: Antecipado | K22: Á Vista : 21+6% | L22: 30 Dias : 21+3% | M22: 60 Dias : 21%
B23: Madeirado / Envidraçado Reto | C23: 1.2 | D23: X | E23: 0.9 | F23: X | G23: 0.78 | I23: ='Tabela Base Casa 7 Brasil'!I21*'Indices de Tabelas'!$C$2 -> 1223.4043 | J23: =ROUNDDOWN((I23*(1-$C$274)*(1-$E$274)*(1-$G$274)),0) -> 872 | K23: =I23*(1-$C$275)*(1-$E$275) -> 908.5 | L23: =I23*(1-$C$276)*(1-$E$275) -> 908.5 | M23: =I23*(1-$C$277) -> 966.48936
B24: Madeirado / Envidraçado Reto | C24: 1.4 | D24: X | E24: 0.9 | F24: X | G24: 0.78 | I24: ='Tabela Base Casa 7 Brasil'!I22*'Indices de Tabelas'!$C$2 -> 1276.5957 | J24: =ROUNDDOWN((I24*(1-$C$274)*(1-$E$274)*(1-$G$274)),0) -> 910 | K24: =I24*(1-$C$275)*(1-$E$275) -> 948 | L24: =I24*(1-$C$276)*(1-$E$275) -> 948 | M24: =I24*(1-$C$277) -> 1008.5106
B25: Madeirado / Envidraçado Reto | C25: 1.6 | D25: X | E25: 1 | F25: X | G25: 0.78 | I25: ='Tabela Base Casa 7 Brasil'!I23*'Indices de Tabelas'!$C$2 -> 1437.6478 | J25: =ROUNDDOWN((I25*(1-$C$274)*(1-$E$274)*(1-$G$274)),0) -> 1024 | K25: =I25*(1-$C$275)*(1-$E$275) -> 1067.5972 | L25: =I25*(1-$C$276)*(1-$E$275) -> 1067.5972 | M25: =I25*(1-$C$277) -> 1135.7417
B26: Madeirado / Envidraçado Reto | C26: 1.8 | D26: X | E26: 1 | F26: X | G26: 0.78 | I26: ='Tabela Base Casa 7 Brasil'!I24*'Indices de Tabelas'!$C$2 -> 1498.227 | J26: =ROUNDDOWN((I26*(1-$C$274)*(1-$E$274)*(1-$G$274)),0) -> 1068 | K26: =I26*(1-$C$275)*(1-$E$275) -> 1112.5833 | L26: =I26*(1-$C$276)*(1-$E$275) -> 1112.5833 | M26: =I26*(1-$C$277) -> 1183.5993
B27: Madeirado / Envidraçado Reto | C27: 2 | D27: X | E27: 1 | F27: X | G27: 0.78 | I27: ='Tabela Base Casa 7 Brasil'!I25*'Indices de Tabelas'!$C$2 -> 1561.7612 | J27: =ROUNDDOWN((I27*(1-$C$274)*(1-$E$274)*(1-$G$274)),0) -> 1113 | K27: =I27*(1-$C$275)*(1-$E$275) -> 1159.7639 | L27: =I27*(1-$C$276)*(1-$E$275) -> 1159.7639 | M27: =I27*(1-$C$277) -> 1233.7914
B28: Madeirado / Envidraçado Reto | C28: 2.2 | D28: X | E28: 1.1 | F28: X | G28: 0.78 | I28: ='Tabela Base Casa 7 Brasil'!I26*'Indices de Tabelas'!$C$2 -> 1767.1395 | J28: =ROUNDDOWN((I28*(1-$C$274)*(1-$E$274)*(1-$G$274)),0) -> 1259 | K28: =I28*(1-$C$275)*(1-$E$275) -> 1312.2778 | L28: =I28*(1-$C$276)*(1-$E$275) -> 1312.2778 | M28: =I28*(1-$C$277) -> 1396.0402
B29: Madeirado / Envidraçado Reto | C29: 1.35 | D29: X | E29: 1.35 | F29: X | G29: 0.78 | I29: ='Tabela Base Casa 7 Brasil'!I27*'Indices de Tabelas'!$C$2 -> 1496.7494 | J29: =ROUNDDOWN((I29*(1-$C$274)*(1-$E$274)*(1-$G$274)),0) -> 1067 | K29: =I29*(1-$C$275)*(1-$E$275) -> 1111.4861 | L29: =I29*(1-$C$276)*(1-$E$275) -> 1111.4861 | M29: =I29*(1-$C$277) -> 1182.432
B30: Madeirado / Envidraçado Moeda OU Copo | C30: 1.2 | D30: X | E30: 0.9 | F30: X | G30: 0.78 | I30: ='Tabela Base Casa 7 Brasil'!I28*'Indices de Tabelas'!$C$2 -> 1255.9102 | J30: =ROUNDDOWN((I30*(1-$C$274)*(1-$E$274)*(1-$G$274)),0) -> 895 | K30: =I30*(1-$C$275)*(1-$E$275) -> 932.63889 | L30: =I30*(1-$C$276)*(1-$E$275) -> 932.63889 | M30: =I30*(1-$C$277) -> 992.16903
B31: Madeirado / Envidraçado Moeda OU Copo | C31: 1.4 | D31: X | E31: 0.9 | F31: X | G31: 0.78 | I31: ='Tabela Base Casa 7 Brasil'!I29*'Indices de Tabelas'!$C$2 -> 1315.0118 | J31: =ROUNDDOWN((I31*(1-$C$274)*(1-$E$274)*(1-$G$274)),0) -> 937 | K31: =I31*(1-$C$275)*(1-$E$275) -> 976.52778 | L31: =I31*(1-$C$276)*(1-$E$275) -> 976.52778 | M31: =I31*(1-$C$277) -> 1038.8593
B32: Madeirado / Envidraçado Moeda OU Copo | C32: 1.6 | D32: X | E32: 1 | F32: X | G32: 0.78 | I32: ='Tabela Base Casa 7 Brasil'!I30*'Indices de Tabelas'!$C$2 -> 1486.4066 | J32: =ROUNDDOWN((I32*(1-$C$274)*(1-$E$274)*(1-$G$274)),0) -> 1059 | K32: =I32*(1-$C$275)*(1-$E$275) -> 1103.8056 | L32: =I32*(1-$C$276)*(1-$E$275) -> 1103.8056 | M32: =I32*(1-$C$277) -> 1174.2612
B33: Madeirado / Envidraçado Moeda OU Copo | C33: 1.8 | D33: X | E33: 1 | F33: X | G33: 0.78 | I33: ='Tabela Base Casa 7 Brasil'!I31*'Indices de Tabelas'!$C$2 -> 1578.0142 | J33: =ROUNDDOWN((I33*(1-$C$274)*(1-$E$274)*(1-$G$274)),0) -> 1124 | K33: =I33*(1-$C$275)*(1-$E$275) -> 1171.8333 | L33: =I33*(1-$C$276)*(1-$E$275) -> 1171.8333 | M33: =I33*(1-$C$277) -> 1246.6312
B34: Madeirado / Envidraçado Moeda OU Copo | C34: 2 | D34: X | E34: 1 | F34: X | G34: 0.78 | I34: ='Tabela Base Casa 7 Brasil'!I32*'Indices de Tabelas'!$C$2 -> 1647.4586 | J34: =ROUNDDOWN((I34*(1-$C$274)*(1-$E$274)*(1-$G$274)),0) -> 1174 | K34: =I34*(1-$C$275)*(1-$E$275) -> 1223.4028 | L34: =I34*(1-$C$276)*(1-$E$275) -> 1223.4028 | M34: =I34*(1-$C$277) -> 1301.4923
B35: Madeirado / Envidraçado Moeda OU Copo | C35: 2.2 | D35: X | E35: 1.1 | F35: X | G35: 0.78 | H35: 0.78 | I35: ='Tabela Base Casa 7 Brasil'!I33*'Indices de Tabelas'!$C$2 -> 1945.922 | J35: =ROUNDDOWN((I35*(1-$C$274)*(1-$E$274)*(1-$G$274)),0) -> 1387 | K35: =I35*(1-$C$275)*(1-$E$275) -> 1445.0417 | L35: =I35*(1-$C$276)*(1-$E$275) -> 1445.0417 | M35: =I35*(1-$C$277) -> 1537.2784
B36: Madeirado / Envidraçado Moeda OU Copo | C36: 1.35 | D36: X | E36: 1.35 | F36: X | G36: 0.78 | I36: ='Tabela Base Casa 7 Brasil'!I34*'Indices de Tabelas'!$C$2 -> 1631.2057 | J36: =ROUNDDOWN((I36*(1-$C$274)*(1-$E$274)*(1-$G$274)),0) -> 1162 | K36: =I36*(1-$C$275)*(1-$E$275) -> 1211.3333 | L36: =I36*(1-$C$276)*(1-$E$275) -> 1211.3333 | M36: =I36*(1-$C$277) -> 1288.6525
B37: Madeirado / Envidraçado Barril | C37: 1.2 | D37: X | E37: 0.9 | F37: X | G37: 0.78 | I37: ='Tabela Base Casa 7 Brasil'!I35*'Indices de Tabelas'!$C$2 -> 1255.9102 | J37: =ROUNDDOWN((I37*(1-$C$274)*(1-$E$274)*(1-$G$274)),0) -> 895 | K37: =I37*(1-$C$275)*(1-$E$275) -> 932.63889 | L37: =I37*(1-$C$276)*(1-$E$275) -> 932.63889 | M37: =I37*(1-$C$277) -> 992.16903
B38: Madeirado / Envidraçado Barril | C38: 1.8 | D38: X | E38: 1 | F38: X | G38: 0.78 | I38: ='Tabela Base Casa 7 Brasil'!I36*'Indices de Tabelas'!$C$2 -> 1578.0142 | J38: =ROUNDDOWN((I38*(1-$C$274)*(1-$E$274)*(1-$G$274)),0) -> 1124 | K38: =I38*(1-$C$275)*(1-$E$275) -> 1171.8333 | L38: =I38*(1-$C$276)*(1-$E$275) -> 1171.8333 | M38: =I38*(1-$C$277) -> 1246.6312
A40: 7MJT015 MESA DE JANTAR MONARCA
B41: Acabamento Tampo | C41: Larg. | E41: Prof. | G41: Alt. | I41: Tabela | J41: Antecipado | K41: Á Vista : 21+6% | L41: 30 Dias : 21+3% | M41: 60 Dias : 21%
B42: Madeirado / Envidraçado Redondo | C42: 1.2 | D42: X | E42: 1.2 | F42: X | G42: 0.78 | I42: ='Tabela Base Casa 7 Brasil'!I40*'Indices de Tabelas'!$C$2 -> 1753.8416 | J42: =ROUNDDOWN((I42*(1-$C$274)*(1-$E$274)*(1-$G$274)),0) -> 1250 | K42: =I42*(1-$C$275)*(1-$E$275) -> 1302.4028 | L42: =I42*(1-$C$276)*(1-$E$275) -> 1302.4028 | M42: =I42*(1-$C$277) -> 1385.5349
B43: Madeirado / Envidraçado Redondo | C43: 1.3 | D43: X | E43: 1.3 | F43: X | G43: 0.78 | I43: ='Tabela Base Casa 7 Brasil'!I41*'Indices de Tabelas'!$C$2 -> 1824.7636 | J43: =ROUNDDOWN((I43*(1-$C$274)*(1-$E$274)*(1-$G$274)),0) -> 1300 | K43: =I43*(1-$C$275)*(1-$E$275) -> 1355.0694 | L43: =I43*(1-$C$276)*(1-$E$275) -> 1355.0694 | M43: =I43*(1-$C$277) -> 1441.5632
B44: Madeirado / Envidraçado Redondo | C44: 1.5 | D44: X | E44: 1.5 | F44: X | G44: 0.78 | I44: ='Tabela Base Casa 7 Brasil'!I42*'Indices de Tabelas'!$C$2 -> 2106.974 | J44: =ROUNDDOWN((I44*(1-$C$274)*(1-$E$274)*(1-$G$274)),0) -> 1502 | K44: =I44*(1-$C$275)*(1-$E$275) -> 1564.6389 | L44: =I44*(1-$C$276)*(1-$E$275) -> 1564.6389 | M44: =I44*(1-$C$277) -> 1664.5095
A46: 7MJT016 MESA DE JANTAR DIAMANTE
B47: Acabamento Tampo | C47: Larg. | E47: Prof. | G47: Alt. | I47: Tabela | J47: Antecipado | K47: Á Vista : 21+6% | L47: 30 Dias : 21+3% | M47: 60 Dias : 21%
...

Sheet Tabela Casa 7 Intersul
L1: Percentual desconto comercial | M1: 0.25
A3: TABELA COMERCIAL CASA 7 - VÁLIDA A PARTIR DE 01/01/2021
A5: Acrescentar 5% referente a IPI
A7: Mesas de Jantar
A9: 7MJT003 MESA DE JANTAR SPIN
B10: Acabamento Tampo | C10: Larg. | E10: Prof. | G10: Alt. | I10: Tabela | J10: Antecipado | K10: Á Vista : 21+6% | L10: 30 Dias : 21+3% | M10: 60 Dias : 21%
B11: Madeirado / Envidraçado Reto | C11: 1.2 | D11: X | E11: 0.9 | F11: X | G11: 0.78 | I11: ='Tabela Base Casa 7 Brasil'!I9*'Indices de Tabelas'!$C$2 -> 1136.2293 | J11: =ROUNDDOWN((I11*(1-$C$274)*(1-$E$274)*(1-$G$274)),0) -> 769 | K11: =I11*(1-$C$275)*(1-$E$275) -> 801.04167 | L11: =I11*(1-$C$276)*(1-$E$275) -> 801.04167 | M11: =I11*(1-$C$277) -> 852.17199
B12: Madeirado / Envidraçado Reto | C12: 1.4 | D12: X | E12: 0.9 | F12: X | G12: 0.78 | I12: ='Tabela Base Casa 7 Brasil'!I10*'Indices de Tabelas'!$C$2 -> 1190.8983 | J12: =ROUNDDOWN((I12*(1-$C$274)*(1-$E$274)*(1-$G$274)),0) -> 806 | K12: =I12*(1-$C$275)*(1-$E$275) -> 839.58333 | L12: =I12*(1-$C$276)*(1-$E$275) -> 839.58333 | M12: =I12*(1-$C$277) -> 893.17376
B13: Madeirado / Envidraçado Reto | C13: 1.35 | D13: X | E13: 1.35 | F13: X | G13: 0.78 | I13: ='Tabela Base Casa 7 Brasil'!I11*'Indices de Tabelas'!$C$2 -> 1499.7045 | J13: =ROUNDDOWN((I13*(1-$C$274)*(1-$E$274)*(1-$G$274)),0) -> 1015 | K13: =I13*(1-$C$275)*(1-$E$275) -> 1057.2917 | L13: =I13*(1-$C$276)*(1-$E$275) -> 1057.2917 | M13: =I13*(1-$C$277) -> 1124.7784
B14: Madeirado / Envidraçado Moeda OU Copo | C14: 1.2 | D14: X | E14: 0.9 | F14: X | G14: 0.78 | I14: ='Tabela Base Casa 7 Brasil'!I12*'Indices de Tabelas'!$C$2 -> 1170.2128 | J14: =ROUNDDOWN((I14*(1-$C$274)*(1-$E$274)*(1-$G$274)),0) -> 792 | K14: =I14*(1-$C$275)*(1-$E$275) -> 825 | L14: =I14*(1-$C$276)*(1-$E$275) -> 825 | M14: =I14*(1-$C$277) -> 877.65957
B15: Madeirado / Envidraçado Moeda OU Copo | C15: 1.4 | D15: X | E15: 0.9 | F15: X | G15: 0.78 | I15: ='Tabela Base Casa 7 Brasil'!I13*'Indices de Tabelas'!$C$2 -> 1239.6572 | J15: =ROUNDDOWN((I15*(1-$C$274)*(1-$E$274)*(1-$G$274)),0) -> 839 | K15: =I15*(1-$C$275)*(1-$E$275) -> 873.95833 | L15: =I15*(1-$C$276)*(1-$E$275) -> 873.95833 | M15: =I15*(1-$C$277) -> 929.74291
B16: Madeirado / Envidraçado Moeda OU Copo | C16: 1.35 | D16: X | E16: 1.35 | F16: X | G16: 0.78 | I16: ='Tabela Base Casa 7 Brasil'!I14*'Indices de Tabelas'!$C$2 -> 1635.6383 | J16: =ROUNDDOWN((I16*(1-$C$274)*(1-$E$274)*(1-$G$274)),0) -> 1107 | K16: =I16*(1-$C$275)*(1-$E$275) -> 1153.125 | L16: =I16*(1-$C$276)*(1-$E$275) -> 1153.125 | M16: =I16*(1-$C$277) -> 1226.7287
B17: Madeirado / Envidraçado Barril | C17: 1.2 | D17: X | E17: 0.9 | F17: X | G17: 0.78 | I17: ='Tabela Base Casa 7 Brasil'!I15*'Indices de Tabelas'!$C$2 -> 1170.2128 | J17: =ROUNDDOWN((I17*(1-$C$274)*(1-$E$274)*(1-$G$274)),0) -> 792 | K17: =I17*(1-$C$275)*(1-$E$275) -> 825 | L17: =I17*(1-$C$276)*(1-$E$275) -> 825 | M17: =I17*(1-$C$277) -> 877.65957
B18: Madeirado / Envidraçado Redonda | C18: 1 | D18: X | E18: 1 | F18: X | G18: 0.78 | I18: ='Tabela Base Casa 7 Brasil'!I16*'Indices de Tabelas'!$C$2 -> 1162.8251 | J18: =ROUNDDOWN((I18*(1-$C$274)*(1-$E$274)*(1-$G$274)),0) -> 787 | K18: =I18*(1-$C$275)*(1-$E$275) -> 819.79167 | L18: =I18*(1-$C$276)*(1-$E$275) -> 819.79167 | M18: =I18*(1-$C$277) -> 872.11879
B19: Madeirado / Envidraçado Redonda | C19: 1.3 | D19: X | E19: 1.3 | F19: X | G19: 0.78 | I19: ='Tabela Base Casa 7 Brasil'!I17*'Indices de Tabelas'!$C$2 -> 1442.0804 | J19: =ROUNDDOWN((I19*(1-$C$274)*(1-$E$274)*(1-$G$274)),0) -> 976 | K19: =I19*(1-$C$275)*(1-$E$275) -> 1016.6667 | L19: =I19*(1-$C$276)*(1-$E$275) -> 1016.6667 | M19: =I19*(1-$C$277) -> 1081.5603
A21: 7MJT005 MESA DE JANTAR TURN
B22: Acabamento Tampo | C22: Larg. | E22: Prof. | G22: Alt. | I22: Tabela | J22: Antecipado | K22: Á Vista : 21+6% | L22: 30 Dias : 21+3% | M22: 60 Dias : 21%
B23: Madeirado / Envidraçado Reto | C23: 1.2 | D23: X | E23: 0.9 | F23: X | G23: 0.78 | I23: ='Tabela Base Casa 7 Brasil'!I21*'Indices de Tabelas'!$C$2 -> 1223.4043 | J23: =ROUNDDOWN((I23*(1-$C$274)*(1-$E$274)*(1-$G$274)),0) -> 828 | K23: =I23*(1-$C$275)*(1-$E$275) -> 862.5 | L23: =I23*(1-$C$276)*(1-$E$275) -> 862.5 | M23: =I23*(1-$C$277) -> 917.55319
B24: Madeirado / Envidraçado Reto | C24: 1.4 | D24: X | E24: 0.9 | F24: X | G24: 0.78 | I24: ='Tabela Base Casa 7 Brasil'!I22*'Indices de Tabelas'!$C$2 -> 1276.5957 | J24: =ROUNDDOWN((I24*(1-$C$274)*(1-$E$274)*(1-$G$274)),0) -> 864 | K24: =I24*(1-$C$275)*(1-$E$275) -> 900 | L24: =I24*(1-$C$276)*(1-$E$275) -> 900 | M24: =I24*(1-$C$277) -> 957.44681
B25: Madeirado / Envidraçado Reto | C25: 1.6 | D25: X | E25: 1 | F25: X | G25: 0.78 | I25: ='Tabela Base Casa 7 Brasil'!I23*'Indices de Tabelas'!$C$2 -> 1437.6478 | J25: =ROUNDDOWN((I25*(1-$C$274)*(1-$E$274)*(1-$G$274)),0) -> 973 | K25: =I25*(1-$C$275)*(1-$E$275) -> 1013.5417 | L25: =I25*(1-$C$276)*(1-$E$275) -> 1013.5417 | M25: =I25*(1-$C$277) -> 1078.2358
B26: Madeirado / Envidraçado Reto | C26: 1.8 | D26: X | E26: 1 | F26: X | G26: 0.78 | I26: ='Tabela Base Casa 7 Brasil'!I24*'Indices de Tabelas'!$C$2 -> 1498.227 | J26: =ROUNDDOWN((I26*(1-$C$274)*(1-$E$274)*(1-$G$274)),0) -> 1014 | K26: =I26*(1-$C$275)*(1-$E$275) -> 1056.25 | L26: =I26*(1-$C$276)*(1-$E$275) -> 1056.25 | M26: =I26*(1-$C$277) -> 1123.6702
B27: Madeirado / Envidraçado Reto | C27: 2 | D27: X | E27: 1 | F27: X | G27: 0.78 | I27: ='Tabela Base Casa 7 Brasil'!I25*'Indices de Tabelas'!$C$2 -> 1561.7612 | J27: =ROUNDDOWN((I27*(1-$C$274)*(1-$E$274)*(1-$G$274)),0) -> 1057 | K27: =I27*(1-$C$275)*(1-$E$275) -> 1101.0417 | L27: =I27*(1-$C$276)*(1-$E$275) -> 1101.0417 | M27: =I27*(1-$C$277) -> 1171.3209
B28: Madeirado / Envidraçado Reto | C28: 2.2 | D28: X | E28: 1.1 | F28: X | G28: 0.78 | I28: ='Tabela Base Casa 7 Brasil'!I26*'Indices de Tabelas'!$C$2 -> 1767.1395 | J28: =ROUNDDOWN((I28*(1-$C$274)*(1-$E$274)*(1-$G$274)),0) -> 1196 | K28: =I28*(1-$C$275)*(1-$E$275) -> 1245.8333 | L28: =I28*(1-$C$276)*(1-$E$275) -> 1245.8333 | M28: =I28*(1-$C$277) -> 1325.3546
B29: Madeirado / Envidraçado Reto | C29: 1.35 | D29: X | E29: 1.35 | F29: X | G29: 0.78 | I29: ='Tabela Base Casa 7 Brasil'!I27*'Indices de Tabelas'!$C$2 -> 1496.7494 | J29: =ROUNDDOWN((I29*(1-$C$274)*(1-$E$274)*(1-$G$274)),0) -> 1013 | K29: =I29*(1-$C$275)*(1-$E$275) -> 1055.2083 | L29: =I29*(1-$C$276)*(1-$E$275) -> 1055.2083 | M29: =I29*(1-$C$277) -> 1122.5621
B30: Madeirado / Envidraçado Moeda OU Copo | C30: 1.2 | D30: X | E30: 0.9 | F30: X | G30: 0.78 | I30: ='Tabela Base Casa 7 Brasil'!I28*'Indices de Tabelas'!$C$2 -> 1255.9102 | J30: =ROUNDDOWN((I30*(1-$C$274)*(1-$E$274)*(1-$G$274)),0) -> 850 | K30: =I30*(1-$C$275)*(1-$E$275) -> 885.41667 | L30: =I30*(1-$C$276)*(1-$E$275) -> 885.41667 | M30: =I30*(1-$C$277) -> 941.93262
B31: Madeirado / Envidraçado Moeda OU Copo | C31: 1.4 | D31: X | E31: 0.9 | F31: X | G31: 0.78 | I31: ='Tabela Base Casa 7 Brasil'!I29*'Indices de Tabelas'!$C$2 -> 1315.0118 | J31: =ROUNDDOWN((I31*(1-$C$274)*(1-$E$274)*(1-$G$274)),0) -> 890 | K31: =I31*(1-$C$275)*(1-$E$275) -> 927.08333 | L31: =I31*(1-$C$276)*(1-$E$275) -> 927.08333 | M31: =I31*(1-$C$277) -> 986.25887
B32: Madeirado / Envidraçado Moeda OU Copo | C32: 1.6 | D32: X | E32: 1 | F32: X | G32: 0.78 | I32: ='Tabela Base Casa 7 Brasil'!I30*'Indices de Tabelas'!$C$2 -> 1486.4066 | J32: =ROUNDDOWN((I32*(1-$C$274)*(1-$E$274)*(1-$G$274)),0) -> 1006 | K32: =I32*(1-$C$275)*(1-$E$275) -> 1047.9167 | L32: =I32*(1-$C$276)*(1-$E$275) -> 1047.9167 | M32: =I32*(1-$C$277) -> 1114.805
B33: Madeirado / Envidraçado Moeda OU Copo | C33: 1.8 | D33: X | E33: 1 | F33: X | G33: 0.78 | I33: ='Tabela Base Casa 7 Brasil'!I31*'Indices de Tabelas'!$C$2 -> 1578.0142 | J33: =ROUNDDOWN((I33*(1-$C$274)*(1-$E$274)*(1-$G$274)),0) -> 1068 | K33: =I33*(1-$C$275)*(1-$E$275) -> 1112.5 | L33: =I33*(1-$C$276)*(1-$E$275) -> 1112.5 | M33: =I33*(1-$C$277) -> 1183.5106
B34: Madeirado / Envidraçado Moeda OU Copo | C34: 2 | D34: X | E34: 1 | F34: X | G34: 0.78 | I34: ='Tabela Base Casa 7 Brasil'!I32*'Indices de Tabelas'!$C$2 -> 1647.4586 | J34: =ROUNDDOWN((I34*(1-$C$274)*(1-$E$274)*(1-$G$274)),0) -> 1115 | K34: =I34*(1-$C$275)*(1-$E$275) -> 1161.4583 | L34: =I34*(1-$C$276)*(1-$E$275) -> 1161.4583 | M34: =I34*(1-$C$277) -> 1235.594
B35: Madeirado / Envidraçado Moeda OU Copo | C35: 2.2 | D35: X | E35: 1.1 | F35: X | G35: 0.78 | H35: 0.78 | I35: ='Tabela Base Casa 7 Brasil'!I33*'Indices de Tabelas'!$C$2 -> 1945.922 | J35: =ROUNDDOWN((I35*(1-$C$274)*(1-$E$274)*(1-$G$274)),0) -> 1317 | K35: =I35*(1-$C$275)*(1-$E$275) -> 1371.875 | L35: =I35*(1-$C$276)*(1-$E$275) -> 1371.875 | M35: =I35*(1-$C$277) -> 1459.4415
B36: Madeirado / Envidraçado Moeda OU Copo | C36: 1.35 | D36: X | E36: 1.35 | F36: X | G36: 0.78 | I36: ='Tabela Base Casa 7 Brasil'!I34*'Indices de Tabelas'!$C$2 -> 1631.2057 | J36: =ROUNDDOWN((I36*(1-$C$274)*(1-$E$274)*(1-$G$274)),0) -> 1104 | K36: =I36*(1-$C$275)*(1-$E$275) -> 1150 | L36: =I36*(1-$C$276)*(1-$E$275) -> 1150 | M36: =I36*(1-$C$277) -> 1223.4043
B37: Madeirado / Envidraçado Barril | C37: 1.2 | D37: X | E37: 0.9 | F37: X | G37: 0.78 | I37: ='Tabela Base Casa 7 Brasil'!I35*'Indices de Tabelas'!$C$2 -> 1255.9102 | J37: =ROUNDDOWN((I37*(1-$C$274)*(1-$E$274)*(1-$G$274)),0) -> 850 | K37: =I37*(1-$C$275)*(1-$E$275) -> 885.41667 | L37: =I37*(1-$C$276)*(1-$E$275) -> 885.41667 | M37: =I37*(1-$C$277) -> 941.93262
B38: Madeirado / Envidraçado Barril | C38: 1.8 | D38: X | E38: 1 | F38: X | G38: 0.78 | I38: ='Tabela Base Casa 7 Brasil'!I36*'Indices de Tabelas'!$C$2 -> 1578.0142 | J38: =ROUNDDOWN((I38*(1-$C$274)*(1-$E$274)*(1-$G$274)),0) -> 1068 | K38: =I38*(1-$C$275)*(1-$E$275) -> 1112.5 | L38: =I38*(1-$C$276)*(1-$E$275) -> 1112.5 | M38: =I38*(1-$C$277) -> 1183.5106
A40: 7MJT015 MESA DE JANTAR MONARCA
B41: Acabamento Tampo | C41: Larg. | E41: Prof. | G41: Alt. | I41: Tabela | J41: Antecipado | K41: Á Vista : 21+6% | L41: 30 Dias : 21+3% | M41: 60 Dias : 21%
B42: Madeirado / Envidraçado Redondo | C42: 1.2 | D42: X | E42: 1.2 | F42: X | G42: 0.78 | I42: ='Tabela Base Casa 7 Brasil'!I40*'Indices de Tabelas'!$C$2 -> 1753.8416 | J42: =ROUNDDOWN((I42*(1-$C$274)*(1-$E$274)*(1-$G$274)),0) -> 1187 | K42: =I42*(1-$C$275)*(1-$E$275) -> 1236.4583 | L42: =I42*(1-$C$276)*(1-$E$275) -> 1236.4583 | M42: =I42*(1-$C$277) -> 1315.3812
B43: Madeirado / Envidraçado Redondo | C43: 1.3 | D43: X | E43: 1.3 | F43: X | G43: 0.78 | I43: ='Tabela Base Casa 7 Brasil'!I41*'Indices de Tabelas'!$C$2 -> 1824.7636 | J43: =ROUNDDOWN((I43*(1-$C$274)*(1-$E$274)*(1-$G$274)),0) -> 1235 | K43: =I43*(1-$C$275)*(1-$E$275) -> 1286.4583 | L43: =I43*(1-$C$276)*(1-$E$275) -> 1286.4583 | M43: =I43*(1-$C$277) -> 1368.5727
B44: Madeirado / Envidraçado Redondo | C44: 1.5 | D44: X | E44: 1.5 | F44: X | G44: 0.78 | I44: ='Tabela Base Casa 7 Brasil'!I42*'Indices de Tabelas'!$C$2 -> 2106.974 | J44: =ROUNDDOWN((I44*(1-$C$274)*(1-$E$274)*(1-$G$274)),0) -> 1426 | K44: =I44*(1-$C$275)*(1-$E$275) -> 1485.4167 | L44: =I44*(1-$C$276)*(1-$E$275) -> 1485.4167 | M44: =I44*(1-$C$277) -> 1580.2305
A46: 7MJT016 MESA DE JANTAR DIAMANTE
B47: Acabamento Tampo | C47: Larg. | E47: Prof. | G47: Alt. | I47: Tabela | J47: Antecipado | K47: Á Vista : 21+6% | L47: 30 Dias : 21+3% | M47: 60 Dias : 21%
...
